Workbook
Name UPDATE: 'Data Sheet'!$E$1

Sheet Dashboard
C1: ='Data Sheet'!B1& " - FINANCIAL MODEL DASHBOARD" -> ASIAN PAINTS LTD - FINANCIAL MODEL DASHBOARD | S1: KEY RATIOS SCORECARD
S2: Metric | U2: FY26 | V2: Hist. avg | W2: vs avg
S3: ='Ratio Analysis'!B5 -> Sales Growth | U3: ='Ratio Analysis'!L5 -> 0.049487961 | V3: ='Ratio Analysis'!N5 -> 0.10496194 | W3: =IF(U3>V3,"▲","▼") -> ▼
S4: ='Ratio Analysis'!B12 -> EBITDA Margin | U4: ='Ratio Analysis'!L12 -> 0.18828172 | V4: ='Ratio Analysis'!N12 -> 0.19401126 | W4: =IF(U4>V4,"▲","▼") -> ▼
S5: ='Ratio Analysis'!B15 -> Net Profit Margin | U5: ='Ratio Analysis'!L15 -> 0.1215548 | V5: ='Ratio Analysis'!N15 -> 0.12471841 | W5: =IF(U5>V5,"▲","▼") -> ▼
S6: ROCE | U6: ='Ratio Analysis'!L21 -> 0.21623587 | V6: ='Ratio Analysis'!N21 -> 0.28515252 | W6: =IF(U6>V6,"▲","▼") -> ▼
S7: ROE | U7: ='Ratio Analysis'!L23 -> 0.20238784 | V7: ='Ratio Analysis'!N23 -> 0.23964869 | W7: =IF(U7>V7,"▲","▼") -> ▼
S8: ='Ratio Analysis'!B24 -> Sustainable Growth Rate | U8: ='Ratio Analysis'!L24 -> 0.078962305 | V8: ='Ratio Analysis'!N24 -> 0.1110223 | W8: =IF(U8>V8,"▲","▼") -> ▼
S9: ='Ratio Analysis'!B25 -> Interest Coverage Ratio | U9: ='Ratio Analysis'!L25 -> 27.99693 | V9: ='Ratio Analysis'!N25 -> 40.757635 | W9: =IF(U9>V9,"▲","▼") -> ▼
S10: ='Ratio Analysis'!B36 -> Inventory Days | U10: ='Ratio Analysis'!L36 -> 89.249888 | V10: ='Ratio Analysis'!N36 -> 96.260625 | W10: =IF(U10>V10,"▲","▼") -> ▼
S11: ▲▼ = FY26 vs historical average (Ratio Analysis). Inventory days: lower is better.
F12: =AVERAGE('Historical FS'!D6:L6) -> 0.10496194
M13: =AVERAGE('Historical FS'!C18:L18) -> 0.19401126 | S13: MARGINS & RETURNS FY17–FY26
N16: FY27 EBITDA SENSITIVITY (₹ Cr)
L18: Base Sales FY27 | N18: =Projections!L6*(1+Dashboard!Q18) -> 39318.457 | O18: ='Sensitivity Analysis'!B3 -> Sales Growth Rate | Q18: ='Sensitivity Analysis'!G3 -> 0.10496194
L19: Base EBITDA FY27 | N19: =N18*Q19 -> 7391.1981 | O19: ='Sensitivity Analysis'!B4 -> EBITDA Margin | Q19: ='Sensitivity Analysis'!G4 -> 0.18798291
L22: =N19 -> 7391.1981 | M22: 0.024961942 | N22: 0.064961942 | O22: 0.10496194 | P22: 0.14496194 | Q22: 0.18496194
L23: 0.14798291 | M23: 5397.1994 | N23: 5607.8296 | O23: 5818.4598 | P23: 6029.0901 | Q23: 6239.7203
L24: 0.16798291 | M24: 6126.6349 | N24: 6365.7319 | O24: 6604.829 | P24: 6843.9261 | Q24: 7083.0231
L25: 0.18798291 | M25: 6856.0703 | N25: 7123.6342 | O25: 7391.1981 | P25: 7658.762 | Q25: 7926.3259
L26: 0.20798291 | M26: 7585.5058 | N26: 7881.5366 | O26: 8177.5673 | P26: 8473.598 | Q26: 8769.6288
L27: 0.22798291 | M27: 8314.9413 | N27: 8639.4389 | O27: 8963.9364 | P27: 9288.434 | Q27: 9612.9316
L29: Range: | M29: ="₹"&TEXT(MIN(M23:Q27),"#,##0")&"- ₹"&TEXT(MAX(M23:Q27),"#,##0") -> ₹5,397- ₹9,613
L30: Vs Base : | M30: =TEXT((M23-O25)/O25,"+0%;-0%")& " / " &TEXT((Q27-O25)/O25,"+0%;-0%") -> -27% / +30%
C34: KEY TAKEAWAYS
C35: Growth has slowed | D35: FY26 sales were ₹35,584 Cr, up 4.9% (FY24 +2.9%, FY25 -4.5%). The 10.5% ten-year mean is lifted by FY22-FY23 (+34% and +18.5%); the median is 7.4%.
C36: Margins are resilient | D36: FY26 EBITDA margin was 18.8% against a 19.4% ten-year mean. EBITDA grew 11.6% on sales growth of 4.9%, recovering from 17.7% in FY25. Net margin is 12.2% and ROE 20.2%.
C37: Profit and EPS | D37: FY26 net profit was ₹4,325 Cr (+18.0%) with EPS of ₹45.1. LTM profit to Jun-26 is ₹4,765 Cr (EPS ₹49.7). Both are on reported profit, after the model correction.
C38: Cash and balance sheet | D38: FY26 operating cash flow was ₹7,088 Cr, about 19.9% of sales. Borrowings rose to ₹3,929 Cr (₹2,290 Cr in FY25). Interest cover is 28.0x, down from 71x in FY17 but still comfortable.
C39: Valuation | D39: At ₹2,370 the stock trades at about 52.6x FY26 EPS (47.7x LTM), 10.6x book value and 31.8x LTM EV/EBITDA, so the price assumes sustained growth.
C40: Forecast | D40: Arithmetic Mean method: FY27E sales ₹39,318 Cr and EBITDA ₹7,391 Cr, rising to ₹64,764 Cr and ₹12,078 Cr by FY32E. The 10.5% growth assumption is well above FY26 (4.9%); Q1 FY27 sales growth of about 18% year on year is the main support. Margin only drifts from 18.8% to 18.65%.
C41: Sensitivity | D41: FY27 EBITDA ranges from ₹5,397 Cr to ₹9,613 Cr (-27% / +30% against base). A 2-point margin step moves EBITDA by about ₹786 Cr, roughly three times a 4-point growth step (about ₹268 Cr), so margin is the bigger swing factor.
C43: NOTES
C44: Source: reviewed Asian Paints model. P&L reconciles to reported PBT, the balance sheet balances, and the cash flow statement ties to the Data Sheet within ±1 Cr.
C45: Price and share count are from the model's Data Sheet. Market cap = price × shares. EV = market cap + FY26 borrowings - FY26 cash & bank (investments are not netted).
C46: Forecast uses the Arithmetic Mean method: sales grow at their mean historical growth (10.5%) and EBITDA at its own mean growth (10.3%), so margin is an output, not an input.

Sheet Data Sheet
A1: COMPANY NAME | B1: ASIAN PAINTS LTD | E1: =IF(B2<>B3, "A NEW VERSION OF THE WORKSHEET IS AVAILABLE", "")
A2: LATEST VERSION | B2: 2.1 | E2: PLEASE DO NOT MAKE ANY CHANGES TO THIS SHEET
A3: CURRENT VERSION | B3: 2.1
A5: META
A6: Number of shares | B6: =IF(B9>0, B9/B8, 0) -> 95.919789
A7: Face Value | B7: 1
A8: Current Price | B8: 2370
A9: Market Capitalization | B9: 227329.9
A15: PROFIT & LOSS
A16: Report Date | B16: 42825 | C16: 43190 | D16: 43555 | E16: 43921 | F16: 44286 | G16: 44651 | H16: 45016 | I16: 45382 | J16: 45747 | K16: 46112
A17: Sales | B17: 15061.99 | C17: 16824.55 | D17: 19240.13 | E17: 20211.25 | F17: 21712.79 | G17: 29101.28 | H17: 34488.59 | I17: 35494.73 | J17: 33905.62 | K17: 35583.54
A18: Raw Material Cost | B18: 7452.6 | C18: 8128.17 | D18: 9974.4 | E18: 9981.99 | F18: 10425.55 | G18: 17123.25 | H18: 18985.53 | I18: 17410.84 | J18: 17504.51 | K18: 17142.01
A19: Change in Inventory | B19: 528.6 | C19: -142.13 | D19: 293.26 | E19: 239.15 | F19: 92.45 | G19: 1324.97 | H19: 309.73 | I19: -363.8 | J19: 205 | K19: -603.68
A20: Power and Fuel | B20: 106.02 | C20: 110.3 | D20: 119.63 | E20: 97.79 | F20: 86.05 | G20: 117.23 | H20: 138.29 | I20: 133.25 | J20: 148.58 | K20: 167.1
A21: Other Mfr. Exp | B21: 1662.75 | C21: 1691.68 | D21: 1862.35 | E21: 1946.12 | F21: 2068.31 | G21: 2880.45 | H21: 2916.2 | I21: 2767.18 | J21: 2687.4 | K21: 2767.11
A22: Employee Cost | B22: 1039.89 | C22: 1121.89 | D22: 1242.69 | E22: 1371.27 | F22: 1547.61 | G22: 1794.61 | H22: 2036.41 | I22: 2334.92 | J22: 2605.78 | K22: 2809.73
A23: Selling and admin | B23: 4364.04 | C23: 2254.92 | D23: 2366.87 | E23: 2311.51 | F23: 2245.69 | G23: 2941.98 | H23: 3500.84 | I23: 3811.86 | J23: 3874.94 | K23: 4112.07
A24: Other Expenses | B24: -2028.47 | C24: 171.45 | D24: 202.51 | E24: 579.95 | F24: 576.43 | G24: 765.12 | H24: 961.21 | I24: 1087.9 | J24: 1283.2 | K24: 1282.11
A25: Other Income | B25: 337.9 | C25: 336.41 | D25: 273.77 | E25: 350.1 | F25: 331.65 | G25: 295.88 | H25: 431.46 | I25: 820.96 | J25: 350.22 | K25: 727.97
A26: Depreciation | B26: 334.79 | C26: 360.47 | D26: 622.14 | E26: 780.5 | F26: 791.27 | G26: 816.36 | H26: 858.02 | I26: 853 | J26: 1026.34 | K26: 1228.85
A27: Interest | B27: 37.33 | C27: 41.47 | D27: 110.47 | E27: 102.33 | F27: 91.63 | G27: 95.41 | H27: 144.45 | I27: 205.17 | J27: 227.02 | K27: 195.41
... A31: Dividend Amount | B31: 987.98 | C31: 834.5 | D31: 1007.16 | E31: 1151.04 | F31: 1712.17 | G31: 1836.87 | H31: 2460.35 | I31: 3194.14 | J31: 2378.82 | K31: 2637.8
A40: Quarters
A41: Report Date | B41: 45382 | C41: 45473 | D41: 45565 | E41: 45657 | F41: 45747 | G41: 45838 | H41: 45930 | I41: 46022 | J41: 46112 | K41: 46203
A42: Sales | B42: 8730.76 | C42: 8969.73 | D42: 8027.54 | E42: 8549.44 | F42: 8358.91 | G42: 8938.55 | H42: 8531.27 | I42: 8867.02 | J42: 9246.7 | K42: 10541.94
A43: Expenses | B43: 7039.39 | C43: 7275.96 | D43: 6788.03 | E43: 6912.71 | F43: 6922.71 | G43: 7313.58 | H43: 7027.89 | I43: 7086.06 | J43: 7460.09 | K43: 8373.18
A44: Other Income | B44: 212.43 | C44: 192.93 | D44: 24.53 | E44: 192.82 | F44: -60.06 | G44: 229.11 | H44: 236.94 | I44: 69.14 | J44: 196.59 | K44: 279.01
A45: Depreciation | B45: 225.61 | C45: 227.7 | D45: 241.99 | E45: 255.55 | F45: 301.1 | G45: 300.87 | H45: 304.93 | I45: 313.07 | J45: 309.98 | K45: 304.19
A46: Interest | B46: 54.1 | C46: 55.38 | D46: 63.01 | E46: 55.84 | F46: 52.79 | G46: 44.5 | H46: 43.87 | I46: 47.94 | J46: 59.1 | K46: 47.83
A47: Profit before tax | B47: 1624.09 | C47: 1603.62 | D47: 959.04 | E47: 1518.16 | F47: 1022.25 | G47: 1508.71 | H47: 1391.52 | I47: 1489.09 | J47: 1614.12 | K47: 2095.75
A48: Tax | B48: 348.79 | C48: 416.83 | D48: 265.38 | E48: 389.73 | F48: 321.42 | G48: 391.66 | H48: 373.29 | I48: 415.17 | J48: 428.63 | K48: 536.3
A49: Net profit | B49: 1256.72 | C49: 1169.98 | D49: 694.64 | E49: 1110.48 | F49: 692.13 | G49: 1099.77 | H49: 993.59 | I49: 1059.87 | J49: 1172.12 | K49: 1539.25
A50: Operating Profit | B50: 1691.37 | C50: 1693.77 | D50: 1239.51 | E50: 1636.73 | F50: 1436.2 | G50: 1624.97 | H50: 1503.38 | I50: 1780.96 | J50: 1786.61 | K50: 2168.76
A55: BALANCE SHEET
A56: Report Date | B56: 42825 | C56: 43190 | D56: 43555 | E56: 43921 | F56: 44286 | G56: 44651 | H56: 45016 | I56: 45382 | J56: 45747 | K56: 46112
A57: Equity Share Capital | B57: 95.92 | C57: 95.92 | D57: 95.92 | E57: 95.92 | F57: 95.92 | G57: 95.92 | H57: 95.92 | I57: 95.92 | J57: 95.92 | K57: 95.92
A58: Reserves | B58: 7507.97 | C58: 8314.31 | D58: 9374.63 | E58: 10034.24 | F58: 12710.37 | G58: 13715.64 | H58: 15896.31 | I58: 18632.38 | J58: 19303.89 | K58: 21275.67
A59: Borrowings | B59: 560.34 | C59: 533.43 | D59: 1319.6 | E59: 1118.5 | F59: 1093.12 | G59: 1586.88 | H59: 1932.62 | I59: 2474.38 | J59: 2290.29 | K59: 3928.93
A60: Other Liabilities | B60: 4240.96 | C60: 4819.82 | D60: 5458.69 | E60: 4889.31 | F60: 6455.93 | G60: 7559.99 | H60: 7854.48 | I60: 8698.09 | J60: 8665.15 | K60: 9218.23
A61: Total | B61: 12405.19 | C61: 13763.48 | D61: 16248.84 | E61: 16137.97 | F61: 20355.34 | G61: 22958.43 | H61: 25779.33 | I61: 29900.77 | J61: 30355.25 | K61: 34518.75
...

Sheet Historical FS
B2: ="Historical Financial Statement -" & 'Data Sheet'!B1 -> Historical Financial Statement -ASIAN PAINTS LTD
B3: Years | C3: ='Data Sheet'!B16 -> 42825 | D3: ='Data Sheet'!C16 -> 43190 | E3: ='Data Sheet'!D16 -> 43555 | F3: ='Data Sheet'!E16 -> 43921 | G3: ='Data Sheet'!F16 -> 44286 | H3: ='Data Sheet'!G16 -> 44651 | I3: ='Data Sheet'!H16 -> 45016 | J3: ='Data Sheet'!I16 -> 45382 | ... L3: ='Data Sheet'!K16 -> 46112 | M3: LTM
A4: # | B4: Income Statement
B5: Sales | C5: =IFERROR('Data Sheet'!B17, 0) -> 15061.99 | D5: =IFERROR('Data Sheet'!C17, 0) -> 16824.55 | E5: =IFERROR('Data Sheet'!D17, 0) -> 19240.13 | F5: =IFERROR('Data Sheet'!E17, 0) -> 20211.25 | G5: =IFERROR('Data Sheet'!F17, 0) -> 21712.79 | H5: =IFERROR('Data Sheet'!G17, 0) -> 29101.28 | I5: =IFERROR('Data Sheet'!H17, 0) -> 34488.59 | J5: =IFERROR('Data Sheet'!I17, 0) -> 35494.73 | ... L5: =IFERROR('Data Sheet'!K17, 0) -> 35583.54 | M5: =IFERROR(SUM('Data Sheet'!H42:K42),0) -> 37186.93
B6: Sales Growth | D6: =D5/C5-1 -> 0.11702039 | E6: =E5/D5-1 -> 0.14357472 | F6: =F5/E5-1 -> 0.050473671 | G6: =G5/F5-1 -> 0.074292288 | H6: =H5/G5-1 -> 0.34028285 | I6: =I5/H5-1 -> 0.18512278 | J6: =J5/I5-1 -> 0.029173127 | K6: =K5/J5-1 -> -0.044770308 | ... M6: =M5/L5-1 -> 0.045059879
B8: COGS | C8: =IFERROR(SUM('Data Sheet'!B18,'Data Sheet'!B20:B22)-1*'Data Sheet'!B19, 0) -> 9732.66 | D8: =IFERROR(SUM('Data Sheet'!C18,'Data Sheet'!C20:C22)-1*'Data Sheet'!C19, 0) -> 11194.17 | E8: =IFERROR(SUM('Data Sheet'!D18,'Data Sheet'!D20:D22)-1*'Data Sheet'!D19, 0) -> 12905.81 | F8: =IFERROR(SUM('Data Sheet'!E18,'Data Sheet'!E20:E22)-1*'Data Sheet'!E19, 0) -> 13158.02 | G8: =IFERROR(SUM('Data Sheet'!F18,'Data Sheet'!F20:F22)-1*'Data Sheet'!F19, 0) -> 14035.07 | H8: =IFERROR(SUM('Data Sheet'!G18,'Data Sheet'!G20:G22)-1*'Data Sheet'!G19, 0) -> 20590.57 | I8: =IFERROR(SUM('Data Sheet'!H18,'Data Sheet'!H20:H22)-1*'Data Sheet'!H19, 0) -> 23766.7 | J8: =IFERROR(SUM('Data Sheet'!I18,'Data Sheet'!I20:I22)-1*'Data Sheet'!I19, 0) -> 23009.99 | ... L8: =IFERROR(SUM('Data Sheet'!K18,'Data Sheet'!K20:K22)-1*'Data Sheet'!K19, 0) -> 23489.63 | M8: =IFERROR(SUM('Data Sheet'!H43:K43),0) -> 29947.22
B9: COGS % Sales | C9: =C8/C5 -> 0.64617358 | D9: =D8/D5 -> 0.66534736 | E9: =E8/E5 -> 0.67077561 | F9: =F8/F5 -> 0.65102455 | G9: =G8/G5 -> 0.64639643 | H9: =H8/H5 -> 0.7075486 | I9: =I8/I5 -> 0.68911776 | J9: =J8/J5 -> 0.64826497 | ... M9: =M8/M5 -> 0.80531574
B11: Gross Profit | C11: =C5-C8 -> 5329.33 | D11: =D5-D8 -> 5630.38 | E11: =E5-E8 -> 6334.32 | F11: =F5-F8 -> 7053.23 | G11: =G5-G8 -> 7677.72 | H11: =H5-H8 -> 8510.71 | I11: =I5-I8 -> 10721.89 | J11: =J5-J8 -> 12484.74 | ... M11: =M5-M8 -> 7239.71
B12: Gross Margin | C12: =C11/C5 -> 0.35382642 | D12: =D11/D5 -> 0.33465264 | E12: =E11/E5 -> 0.32922439 | F12: =F11/F5 -> 0.34897545 | G12: =G11/G5 -> 0.35360357 | H12: =H11/H5 -> 0.2924514 | I12: =I11/I5 -> 0.31088224 | J12: =J11/J5 -> 0.35173503 | ... M12: =M11/M5 -> 0.19468426
B14: Selling & General Expenses | C14: =IFERROR(SUM('Data Sheet'!B23,'Data Sheet'!B24),0) -> 2335.57 | D14: =IFERROR(SUM('Data Sheet'!C23,'Data Sheet'!C24),0) -> 2426.37 | E14: =IFERROR(SUM('Data Sheet'!D23,'Data Sheet'!D24),0) -> 2569.38 | F14: =IFERROR(SUM('Data Sheet'!E23,'Data Sheet'!E24),0) -> 2891.46 | G14: =IFERROR(SUM('Data Sheet'!F23,'Data Sheet'!F24),0) -> 2822.12 | H14: =IFERROR(SUM('Data Sheet'!G23,'Data Sheet'!G24),0) -> 3707.1 | I14: =IFERROR(SUM('Data Sheet'!H23,'Data Sheet'!H24),0) -> 4462.05 | J14: =IFERROR(SUM('Data Sheet'!I23,'Data Sheet'!I24),0) -> 4899.76 | ... L14: =IFERROR(SUM('Data Sheet'!K23,'Data Sheet'!K24),0) -> 5394.18
B15: S&G Exp %Sales | C15: =C14/C5 -> 0.15506384 | D15: =D14/D5 -> 0.14421604 | E15: =E14/E5 -> 0.13354276 | F15: =F14/F5 -> 0.14306191 | G15: =G14/G5 -> 0.12997501 | H15: =H14/H5 -> 0.12738615 | I15: =I14/I5 -> 0.12937757 | J15: =J14/J5 -> 0.1380419 | ... L15: =L14/L5 -> 0.151592
B17: EBITDA | C17: =IFERROR('Historical FS'!C11-'Historical FS'!C14,0) -> 2993.76 | D17: =IFERROR('Historical FS'!D11-'Historical FS'!D14,0) -> 3204.01 | E17: =IFERROR('Historical FS'!E11-'Historical FS'!E14,0) -> 3764.94 | F17: =IFERROR('Historical FS'!F11-'Historical FS'!F14,0) -> 4161.77 | G17: =IFERROR('Historical FS'!G11-'Historical FS'!G14,0) -> 4855.6 | H17: =IFERROR('Historical FS'!H11-'Historical FS'!H14,0) -> 4803.61 | I17: =IFERROR('Historical FS'!I11-'Historical FS'!I14,0) -> 6259.84 | J17: =IFERROR('Historical FS'!J11-'Historical FS'!J14,0) -> 7584.98 | ... L17: =IFERROR('Historical FS'!L11-'Historical FS'!L14,0) -> 6699.73 | M17: =IFERROR(SUM('Data Sheet'!H50:K50),0) -> 7239.71
B18: EBITDA Margins | C18: =C17/C5 -> 0.19876258 | D18: =D17/D5 -> 0.19043659 | E18: =E17/E5 -> 0.19568163 | F18: =F17/F5 -> 0.20591354 | G18: =G17/G5 -> 0.22362856 | H18: =H17/H5 -> 0.16506525 | I18: =I17/I5 -> 0.18150467 | J18: =J17/J5 -> 0.21369313 | ... M18: =M17/M5 -> 0.19468426
B20: Depreciation | C20: =IFERROR('Data Sheet'!B26,0) -> 334.79 | D20: =IFERROR('Data Sheet'!C26,0) -> 360.47 | E20: =IFERROR('Data Sheet'!D26,0) -> 622.14 | F20: =IFERROR('Data Sheet'!E26,0) -> 780.5 | G20: =IFERROR('Data Sheet'!F26,0) -> 791.27 | H20: =IFERROR('Data Sheet'!G26,0) -> 816.36 | I20: =IFERROR('Data Sheet'!H26,0) -> 858.02 | J20: =IFERROR('Data Sheet'!I26,0) -> 853 | ... L20: =IFERROR('Data Sheet'!K26,0) -> 1228.85 | M20: =IFERROR(SUM('Data Sheet'!H45:K45),0) -> 1232.17
B21: Depreciation % Sales | C21: =C20/C5 -> 0.022227475 | D21: =D20/D5 -> 0.021425239 | E21: =E20/E5 -> 0.03233554 | F21: =F20/F5 -> 0.038617107 | G21: =G20/G5 -> 0.036442576 | H21: =H20/H5 -> 0.028052374 | I21: =I20/I5 -> 0.024878373 | J21: =J20/J5 -> 0.024031737 | ... M21: =M20/M5 -> 0.033134491
B23: EBIT | C23: =IFERROR(C17-C20,0) -> 2658.97 | D23: =IFERROR(D17-D20,0) -> 2843.54 | E23: =IFERROR(E17-E20,0) -> 3142.8 | F23: =IFERROR(F17-F20,0) -> 3381.27 | G23: =IFERROR(G17-G20,0) -> 4064.33 | H23: =IFERROR(H17-H20,0) -> 3987.25 | I23: =IFERROR(I17-I20,0) -> 5401.82 | J23: =IFERROR(J17-J20,0) -> 6731.98 | ... M23: =IFERROR(M17-M20,0) -> 6007.54
B24: EBIT %Sales | C24: =C23/C5 -> 0.17653511 | D24: =D23/D5 -> 0.16901136 | E24: =E23/E5 -> 0.16334609 | F24: =F23/F5 -> 0.16729643 | G24: =G23/G5 -> 0.18718599 | H24: =H23/H5 -> 0.13701287 | I24: =I23/I5 -> 0.15662629 | J24: =J23/J5 -> 0.18966139 | ... M24: =M23/M5 -> 0.16154977
B26: Other Income | C26: =IFERROR('Data Sheet'!B25,0) -> 337.9 | D26: =IFERROR('Data Sheet'!C25,0) -> 336.41 | E26: =IFERROR('Data Sheet'!D25,0) -> 273.77 | F26: =IFERROR('Data Sheet'!E25,0) -> 350.1 | G26: =IFERROR('Data Sheet'!F25,0) -> 331.65 | H26: =IFERROR('Data Sheet'!G25,0) -> 295.88 | I26: =IFERROR('Data Sheet'!H25,0) -> 431.46 | J26: =IFERROR('Data Sheet'!I25,0) -> 820.96 | ... L26: =IFERROR('Data Sheet'!K25,0) -> 727.97 | M26: =IFERROR(SUM('Data Sheet'!H44:K44),0) -> 781.68
B27: Other Income % Sales | C27: =C26/C5 -> 0.022433955 | D27: =D26/D5 -> 0.019995186 | E27: =E26/E5 -> 0.014229114 | F27: =F26/F5 -> 0.017322036 | G27: =G26/G5 -> 0.015274407 | H27: =H26/H5 -> 0.01016725 | I27: =I26/I5 -> 0.012510224 | J27: =J26/J5 -> 0.023129067 | ... M27: =M26/M5 -> 0.021020289
B29: Interest | C29: =IFERROR('Data Sheet'!B27,0) -> 37.33 | D29: =IFERROR('Data Sheet'!C27,0) -> 41.47 | E29: =IFERROR('Data Sheet'!D27,0) -> 110.47 | F29: =IFERROR('Data Sheet'!E27,0) -> 102.33 | G29: =IFERROR('Data Sheet'!F27,0) -> 91.63 | H29: =IFERROR('Data Sheet'!G27,0) -> 95.41 | I29: =IFERROR('Data Sheet'!H27,0) -> 144.45 | J29: =IFERROR('Data Sheet'!I27,0) -> 205.17 | ... L29: =IFERROR('Data Sheet'!K27,0) -> 195.41 | M29: =IFERROR(SUM('Data Sheet'!H46:K46),0) -> 198.74
B30: Interest % Sales | C30: =C29/C5 -> 0.0024784242 | D30: =D29/D5 -> 0.0024648505 | E30: =E29/E5 -> 0.0057416452 | F30: =F29/F5 -> 0.0050630218 | G30: =G29/G5 -> 0.0042200933 | H30: =H29/H5 -> 0.0032785499 | I30: =I29/I5 -> 0.0041883417 | J30: =J29/J5 -> 0.0057802947 | ... M30: =M29/M5 -> 0.0053443508
B32: PBT | C32: =C23+C26-C29 -> 2959.54 | D32: =D23+D26-D29 -> 3138.48 | E32: =E23+E26-E29 -> 3306.1 | F32: =F23+F26-F29 -> 3629.04 | G32: =G23+G26-G29 -> 4304.35 | H32: =H23+H26-H29 -> 4187.72 | I32: =I23+I26-I29 -> 5688.83 | J32: =J23+J26-J29 -> 7347.77 | ... M32: =M23+M26-M29 -> 6590.48
B33: PBT % Sales | C33: =C32/C5 -> 0.19649064 | D33: =D32/D5 -> 0.18654169 | E33: =E32/E5 -> 0.17183356 | F33: =F32/F5 -> 0.17955545 | G33: =G32/G5 -> 0.1982403 | H33: =H32/H5 -> 0.14390157 | I33: =I32/I5 -> 0.16494818 | J33: =J32/J5 -> 0.20701017 | ... M33: =M32/M5 -> 0.17722571
B35: Tax | C35: =IFERROR('Data Sheet'!B29,0) -> 943.29 | D35: =IFERROR('Data Sheet'!C29,0) -> 1040.96 | E35: =IFERROR('Data Sheet'!D29,0) -> 1098.06 | F35: =IFERROR('Data Sheet'!E29,0) -> 854.85 | G35: =IFERROR('Data Sheet'!F29,0) -> 1097.6 | H35: =IFERROR('Data Sheet'!G29,0) -> 1102.91 | I35: =IFERROR('Data Sheet'!H29,0) -> 1493.5 | J35: =IFERROR('Data Sheet'!I29,0) -> 1790.08 | ... L35: =IFERROR('Data Sheet'!K29,0) -> 1608.75 | M35: =IFERROR(SUM('Data Sheet'!H48:K48),0) -> 1753.39
B36: Effective Tax Rate% | C36: =C35/C32 -> 0.31872859 | D36: =D35/D32 -> 0.33167648 | E36: =E35/E32 -> 0.33213151 | F36: =F35/F32 -> 0.23555816 | G36: =G35/G32 -> 0.25499785 | H36: =H35/H32 -> 0.26336766 | I36: =I35/I32 -> 0.26253201 | J36: =J35/J32 -> 0.24362221 | ... M36: =M35/M32 -> 0.26604891
B37: Other Adjustments | C37: =C39-(C32-C35) -> -76.82 | D37: =D39-(D32-D35) -> -58.59 | E37: =E39-(E32-E35) -> -52.12 | F37: =F39-(F32-F35) -> -69.02 | G37: =G39-(G32-G35) -> -67.46 | H37: =H39-(H32-H35) -> -54.24 | I37: =I39-(I32-I35) -> -88.88 | J37: =J39-(J32-J35) -> -97.46 | ... M37: =M39-(M32-M35) -> -72.26
B39: Net Profit | C39: =IFERROR('Data Sheet'!B30,0) -> 1939.43 | D39: =IFERROR('Data Sheet'!C30,0) -> 2038.93 | E39: =IFERROR('Data Sheet'!D30,0) -> 2155.92 | F39: =IFERROR('Data Sheet'!E30,0) -> 2705.17 | G39: =IFERROR('Data Sheet'!F30,0) -> 3139.29 | H39: =IFERROR('Data Sheet'!G30,0) -> 3030.57 | I39: =IFERROR('Data Sheet'!H30,0) -> 4106.45 | J39: =IFERROR('Data Sheet'!I30,0) -> 5460.23 | ... L39: =IFERROR('Data Sheet'!K30,0) -> 4325.35 | M39: =SUM('Data Sheet'!H49:K49) -> 4764.83
B40: Net Margins% | C40: =C39/C5 -> 0.1287632 | D40: =D39/D5 -> 0.12118779 | E40: =E39/E5 -> 0.1120533 | F40: =F39/F5 -> 0.13384476 | G40: =G39/G5 -> 0.14458252 | H40: =H39/H5 -> 0.10413872 | I40: =I39/I5 -> 0.11906691 | J40: =J39/J5 -> 0.15383213 | ... M40: =M39/M5 -> 0.12813185
B42: No. of Equity Shares | C42: =IFERROR('Data Sheet'!B93,0) -> 95.92 | D42: =IFERROR('Data Sheet'!C93,0) -> 95.92 | E42: =IFERROR('Data Sheet'!D93,0) -> 95.92 | F42: =IFERROR('Data Sheet'!E93,0) -> 95.92 | G42: =IFERROR('Data Sheet'!F93,0) -> 95.92 | H42: =IFERROR('Data Sheet'!G93,0) -> 95.92 | I42: =IFERROR('Data Sheet'!H93,0) -> 95.92 | J42: =IFERROR('Data Sheet'!I93,0) -> 95.92 | ... L42: =IFERROR('Data Sheet'!K93,0) -> 95.92 | M42: =IFERROR('Data Sheet'!K93,0) -> 95.92
B44: Earnings Per Share | C44: =C39/C42 -> 20.219245 | D44: =D39/D42 -> 21.256568 | E44: =E39/E42 -> 22.47623 | F44: =F39/F42 -> 28.202356 | G44: =G39/G42 -> 32.728211 | H44: =H39/H42 -> 31.594766 | I44: =I39/I42 -> 42.811197 | J44: =J39/J42 -> 56.924833 | ... M44: =M39/M42 -> 49.675042
B45: EPS Growth % | D45: =D44/C44-1 -> 0.051303734 | E45: =E44/D44-1 -> 0.057378135 | F45: =F44/E44-1 -> 0.25476363 | G45: =G44/F44-1 -> 0.1604779 | H45: =H44/G44-1 -> -0.034632035 | I45: =I44/H44-1 -> 0.35500912 | J45: =J44/I44-1 -> 0.32967161 | K45: =K44/J44-1 -> -0.32837445 | ... M45: =M44/L44-1 -> 0.10160565
B47: Dividend Per Share | C47: =IFERROR('Data Sheet'!B31/'Historical FS'!C42,0) -> 10.300042 | D47: =IFERROR('Data Sheet'!C31/'Historical FS'!D42,0) -> 8.6999583 | E47: =IFERROR('Data Sheet'!D31/'Historical FS'!E42,0) -> 10.5 | F47: =IFERROR('Data Sheet'!E31/'Historical FS'!F42,0) -> 12 | G47: =IFERROR('Data Sheet'!F31/'Historical FS'!G42,0) -> 17.849979 | H47: =IFERROR('Data Sheet'!G31/'Historical FS'!H42,0) -> 19.150021 | I47: =IFERROR('Data Sheet'!H31/'Historical FS'!I42,0) -> 25.650021 | J47: =IFERROR('Data Sheet'!I31/'Historical FS'!J42,0) -> 33.300042 | ... L47: =IFERROR('Data Sheet'!K31/'Historical FS'!L42,0) -> 27.5
B48: Dividend Payout Ratio | C48: =C47/C44 -> 0.50941772 | D48: =D47/D44 -> 0.4092833 | E48: =E47/E44 -> 0.46716019 | F48: =F47/F44 -> 0.42549636 | G48: =G47/G44 -> 0.54540039 | H48: =H47/H44 -> 0.6061137 | I48: =I47/I44 -> 0.59914281 | J48: =J47/J44 -> 0.58498268 | ... L48: =L47/L44 -> 0.6098466
B50: Retained Earnings | C50: =IFERROR(IF(C44>C47,1-C48,0),0) -> 0.49058228 | D50: =IFERROR(IF(D44>D47,1-D48,0),0) -> 0.5907167 | E50: =IFERROR(IF(E44>E47,1-E48,0),0) -> 0.53283981 | F50: =IFERROR(IF(F44>F47,1-F48,0),0) -> 0.57450364 | G50: =IFERROR(IF(G44>G47,1-G48,0),0) -> 0.45459961 | H50: =IFERROR(IF(H44>H47,1-H48,0),0) -> 0.3938863 | I50: =IFERROR(IF(I44>I47,1-I48,0),0) -> 0.40085719 | J50: =IFERROR(IF(J44>J47,1-J48,0),0) -> 0.41501732 | ... L50: =IFERROR(IF(L44>L47,1-L48,0),0) -> 0.3901534
A52: # | B52: Balance Sheet
B53: Equity Share Capital | C53: =IFERROR('Data Sheet'!B57,0) -> 95.92 | D53: =IFERROR('Data Sheet'!C57,0) -> 95.92 | E53: =IFERROR('Data Sheet'!D57,0) -> 95.92 | F53: =IFERROR('Data Sheet'!E57,0) -> 95.92 | G53: =IFERROR('Data Sheet'!F57,0) -> 95.92 | H53: =IFERROR('Data Sheet'!G57,0) -> 95.92 | I53: =IFERROR('Data Sheet'!H57,0) -> 95.92 | J53: =IFERROR('Data Sheet'!I57,0) -> 95.92 | ... L53: =IFERROR('Data Sheet'!K57,0) -> 95.92
B54: Reserves | C54: =IFERROR('Data Sheet'!B58,0) -> 7507.97 | D54: =IFERROR('Data Sheet'!C58,0) -> 8314.31 | E54: =IFERROR('Data Sheet'!D58,0) -> 9374.63 | F54: =IFERROR('Data Sheet'!E58,0) -> 10034.24 | G54: =IFERROR('Data Sheet'!F58,0) -> 12710.37 | H54: =IFERROR('Data Sheet'!G58,0) -> 13715.64 | I54: =IFERROR('Data Sheet'!H58,0) -> 15896.31 | J54: =IFERROR('Data Sheet'!I58,0) -> 18632.38 | ... L54: =IFERROR('Data Sheet'!K58,0) -> 21275.67
B55: Borrowings | C55: =IFERROR('Data Sheet'!B59,0) -> 560.34 | D55: =IFERROR('Data Sheet'!C59,0) -> 533.43 | E55: =IFERROR('Data Sheet'!D59,0) -> 1319.6 | F55: =IFERROR('Data Sheet'!E59,0) -> 1118.5 | G55: =IFERROR('Data Sheet'!F59,0) -> 1093.12 | H55: =IFERROR('Data Sheet'!G59,0) -> 1586.88 | I55: =IFERROR('Data Sheet'!H59,0) -> 1932.62 | J55: =IFERROR('Data Sheet'!I59,0) -> 2474.38 | ... L55: =IFERROR('Data Sheet'!K59,0) -> 3928.93
B56: Other Liabilities | C56: =IFERROR('Data Sheet'!B60,0) -> 4240.96 | D56: =IFERROR('Data Sheet'!C60,0) -> 4819.82 | E56: =IFERROR('Data Sheet'!D60,0) -> 5458.69 | F56: =IFERROR('Data Sheet'!E60,0) -> 4889.31 | G56: =IFERROR('Data Sheet'!F60,0) -> 6455.93 | H56: =IFERROR('Data Sheet'!G60,0) -> 7559.99 | I56: =IFERROR('Data Sheet'!H60,0) -> 7854.48 | J56: =IFERROR('Data Sheet'!I60,0) -> 8698.09 | ... L56: =IFERROR('Data Sheet'!K60,0) -> 9218.23
B57: Total Liabilities | C57: =IFERROR(SUM(C53:C56),0) -> 12405.19 | D57: =IFERROR(SUM(D53:D56),0) -> 13763.48 | E57: =IFERROR(SUM(E53:E56),0) -> 16248.84 | F57: =IFERROR(SUM(F53:F56),0) -> 16137.97 | G57: =IFERROR(SUM(G53:G56),0) -> 20355.34 | H57: =IFERROR(SUM(H53:H56),0) -> 22958.43 | I57: =IFERROR(SUM(I53:I56),0) -> 25779.33 | J57: =IFERROR(SUM(J53:J56),0) -> 29900.77 | ... L57: =IFERROR(SUM(L53:L56),0) -> 34518.75
...

Sheet Ratio Analysis
B2: ="Ratio Analysis -" & 'Data Sheet'!B1 -> Ratio Analysis -ASIAN PAINTS LTD
B3: Years | C3: ='Data Sheet'!B16 -> 42825 | D3: ='Data Sheet'!C16 -> 43190 | E3: ='Data Sheet'!D16 -> 43555 | F3: ='Data Sheet'!E16 -> 43921 | G3: ='Data Sheet'!F16 -> 44286 | H3: ='Data Sheet'!G16 -> 44651 | I3: ='Data Sheet'!H16 -> 45016 | J3: ='Data Sheet'!I16 -> 45382 | ... L3: ='Data Sheet'!K16 -> 46112 | M3: Trend | N3: Mean | O3: Median
B5: Sales Growth | D5: =IFERROR('Historical FS'!D6,0) -> 0.11702039 | E5: =IFERROR('Historical FS'!E6,0) -> 0.14357472 | F5: =IFERROR('Historical FS'!F6,0) -> 0.050473671 | G5: =IFERROR('Historical FS'!G6,0) -> 0.074292288 | H5: =IFERROR('Historical FS'!H6,0) -> 0.34028285 | I5: =IFERROR('Historical FS'!I6,0) -> 0.18512278 | J5: =IFERROR('Historical FS'!J6,0) -> 0.029173127 | K5: =IFERROR('Historical FS'!K6,0) -> -0.044770308 | L5: =IFERROR('Historical FS'!L6,0) -> 0.049487961 | N5: =IFERROR(AVERAGE(D5:L5),0) -> 0.10496194 | O5: =IFERROR(MEDIAN(D5:L5),0) -> 0.074292288
B6: EBITDA Growth | D6: =IFERROR('Historical FS'!D17/'Historical FS'!C17-1,0) -> 0.070229411 | E6: =IFERROR('Historical FS'!E17/'Historical FS'!D17-1,0) -> 0.17507124 | F6: =IFERROR('Historical FS'!F17/'Historical FS'!E17-1,0) -> 0.10540141 | G6: =IFERROR('Historical FS'!G17/'Historical FS'!F17-1,0) -> 0.16671512 | H6: =IFERROR('Historical FS'!H17/'Historical FS'!G17-1,0) -> -0.010707225 | I6: =IFERROR('Historical FS'!I17/'Historical FS'!H17-1,0) -> 0.30315325 | J6: =IFERROR('Historical FS'!J17/'Historical FS'!I17-1,0) -> 0.21168912 | K6: =IFERROR('Historical FS'!K17/'Historical FS'!J17-1,0) -> -0.20814425 | L6: =IFERROR('Historical FS'!L17/'Historical FS'!K17-1,0) -> 0.11546716 | N6: =IFERROR(AVERAGE(D6:L6),0) -> 0.10320836 | O6: =IFERROR(MEDIAN(D6:L6),0) -> 0.11546716
B7: EBIT Growth | D7: =IFERROR('Historical FS'!D23/'Historical FS'!C23-1,0) -> 0.069414096 | E7: =IFERROR('Historical FS'!E23/'Historical FS'!D23-1,0) -> 0.10524206 | F7: =IFERROR('Historical FS'!F23/'Historical FS'!E23-1,0) -> 0.075878198 | G7: =IFERROR('Historical FS'!G23/'Historical FS'!F23-1,0) -> 0.20201285 | H7: =IFERROR('Historical FS'!H23/'Historical FS'!G23-1,0) -> -0.018964995 | I7: =IFERROR('Historical FS'!I23/'Historical FS'!H23-1,0) -> 0.35477334 | J7: =IFERROR('Historical FS'!J23/'Historical FS'!I23-1,0) -> 0.24624293 | K7: =IFERROR('Historical FS'!K23/'Historical FS'!J23-1,0) -> -0.26026667 | L7: =IFERROR('Historical FS'!L23/'Historical FS'!K23-1,0) -> 0.098598959 | N7: =IFERROR(AVERAGE(D7:L7),0) -> 0.096992308 | O7: =IFERROR(MEDIAN(D7:L7),0) -> 0.098598959
B8: Net Profit Growth | D8: =IFERROR('Historical FS'!D39/'Historical FS'!C39-1,0) -> 0.051303734 | E8: =IFERROR('Historical FS'!E39/'Historical FS'!D39-1,0) -> 0.057378135 | F8: =IFERROR('Historical FS'!F39/'Historical FS'!E39-1,0) -> 0.25476363 | G8: =IFERROR('Historical FS'!G39/'Historical FS'!F39-1,0) -> 0.1604779 | H8: =IFERROR('Historical FS'!H39/'Historical FS'!G39-1,0) -> -0.034632035 | I8: =IFERROR('Historical FS'!I39/'Historical FS'!H39-1,0) -> 0.35500912 | J8: =IFERROR('Historical FS'!J39/'Historical FS'!I39-1,0) -> 0.32967161 | K8: =IFERROR('Historical FS'!K39/'Historical FS'!J39-1,0) -> -0.32837445 | L8: =IFERROR('Historical FS'!L39/'Historical FS'!K39-1,0) -> 0.1794597 | N8: =IFERROR(AVERAGE(D8:L8),0) -> 0.11389526 | O8: =IFERROR(MEDIAN(D8:L8),0) -> 0.1604779
B9: Dividend Growth | D9: =IFERROR('Historical FS'!D47/'Historical FS'!C47-1,0) -> -0.15534727 | E9: =IFERROR('Historical FS'!E47/'Historical FS'!D47-1,0) -> 0.20690234 | F9: =IFERROR('Historical FS'!F47/'Historical FS'!E47-1,0) -> 0.14285714 | G9: =IFERROR('Historical FS'!G47/'Historical FS'!F47-1,0) -> 0.48749826 | H9: =IFERROR('Historical FS'!H47/'Historical FS'!G47-1,0) -> 0.072831553 | I9: =IFERROR('Historical FS'!I47/'Historical FS'!H47-1,0) -> 0.33942522 | J9: =IFERROR('Historical FS'!J47/'Historical FS'!I47-1,0) -> 0.29824618 | K9: =IFERROR('Historical FS'!K47/'Historical FS'!J47-1,0) -> -0.25525494 | L9: =IFERROR('Historical FS'!L47/'Historical FS'!K47-1,0) -> 0.1088691 | N9: =IFERROR(AVERAGE(D9:L9),0) -> 0.13844751 | O9: =IFERROR(MEDIAN(D9:L9),0) -> 0.14285714
B11: Gross Margin | C11: =IFERROR('Historical FS'!C12,0) -> 0.35382642 | D11: =IFERROR('Historical FS'!D12,0) -> 0.33465264 | E11: =IFERROR('Historical FS'!E12,0) -> 0.32922439 | F11: =IFERROR('Historical FS'!F12,0) -> 0.34897545 | G11: =IFERROR('Historical FS'!G12,0) -> 0.35360357 | H11: =IFERROR('Historical FS'!H12,0) -> 0.2924514 | I11: =IFERROR('Historical FS'!I12,0) -> 0.31088224 | J11: =IFERROR('Historical FS'!J12,0) -> 0.35173503 | ... L11: =IFERROR('Historical FS'!L12,0) -> 0.33987372 | N11: =IFERROR(AVERAGE(C11:L11),0) -> 0.33445021 | O11: =IFERROR(MEDIAN(C11:L11),0) -> 0.33726318
B12: EBITDA Margin | C12: =IFERROR('Historical FS'!C18,0) -> 0.19876258 | D12: =IFERROR('Historical FS'!D18,0) -> 0.19043659 | E12: =IFERROR('Historical FS'!E18,0) -> 0.19568163 | F12: =IFERROR('Historical FS'!F18,0) -> 0.20591354 | G12: =IFERROR('Historical FS'!G18,0) -> 0.22362856 | H12: =IFERROR('Historical FS'!H18,0) -> 0.16506525 | I12: =IFERROR('Historical FS'!I18,0) -> 0.18150467 | J12: =IFERROR('Historical FS'!J18,0) -> 0.21369313 | ... L12: =IFERROR('Historical FS'!L18,0) -> 0.18828172 | N12: =IFERROR(AVERAGE(C12:L12),0) -> 0.19401126 | O12: =IFERROR(MEDIAN(C12:L12),0) -> 0.19305911
B13: EBIT Margin | C13: =IFERROR('Historical FS'!C24,0) -> 0.17653511 | D13: =IFERROR('Historical FS'!D24,0) -> 0.16901136 | E13: =IFERROR('Historical FS'!E24,0) -> 0.16334609 | F13: =IFERROR('Historical FS'!F24,0) -> 0.16729643 | G13: =IFERROR('Historical FS'!G24,0) -> 0.18718599 | H13: =IFERROR('Historical FS'!H24,0) -> 0.13701287 | I13: =IFERROR('Historical FS'!I24,0) -> 0.15662629 | J13: =IFERROR('Historical FS'!J24,0) -> 0.18966139 | ... L13: =IFERROR('Historical FS'!L24,0) -> 0.15374749 | N13: =IFERROR(AVERAGE(C13:L13),0) -> 0.16472975 | O13: =IFERROR(MEDIAN(C13:L13),0) -> 0.16532126
B14: PBT Margin | C14: =IFERROR('Historical FS'!C33,0) -> 0.19649064 | D14: =IFERROR('Historical FS'!D33,0) -> 0.18654169 | E14: =IFERROR('Historical FS'!E33,0) -> 0.17183356 | F14: =IFERROR('Historical FS'!F33,0) -> 0.17955545 | G14: =IFERROR('Historical FS'!G33,0) -> 0.1982403 | H14: =IFERROR('Historical FS'!H33,0) -> 0.14390157 | I14: =IFERROR('Historical FS'!I33,0) -> 0.16494818 | J14: =IFERROR('Historical FS'!J33,0) -> 0.20701017 | ... L14: =IFERROR('Historical FS'!L33,0) -> 0.16871396 | N14: =IFERROR(AVERAGE(C14:L14),0) -> 0.17677436 | O14: =IFERROR(MEDIAN(C14:L14),0) -> 0.1756945
B15: Net Profit Margin | C15: =IFERROR('Historical FS'!C40,0) -> 0.1287632 | D15: =IFERROR('Historical FS'!D40,0) -> 0.12118779 | E15: =IFERROR('Historical FS'!E40,0) -> 0.1120533 | F15: =IFERROR('Historical FS'!F40,0) -> 0.13384476 | G15: =IFERROR('Historical FS'!G40,0) -> 0.14458252 | H15: =IFERROR('Historical FS'!H40,0) -> 0.10413872 | I15: =IFERROR('Historical FS'!I40,0) -> 0.11906691 | J15: =IFERROR('Historical FS'!J40,0) -> 0.15383213 | ... L15: =IFERROR('Historical FS'!L40,0) -> 0.1215548 | N15: =IFERROR(AVERAGE(C15:L15),0) -> 0.12471841 | O15: =IFERROR(MEDIAN(C15:L15),0) -> 0.12137129
B17: SalesExpenses%Sales | C17: =IFERROR('Historical FS'!C15,0) -> 0.15506384 | D17: =IFERROR('Historical FS'!D15,0) -> 0.14421604 | E17: =IFERROR('Historical FS'!E15,0) -> 0.13354276 | F17: =IFERROR('Historical FS'!F15,0) -> 0.14306191 | G17: =IFERROR('Historical FS'!G15,0) -> 0.12997501 | H17: =IFERROR('Historical FS'!H15,0) -> 0.12738615 | I17: =IFERROR('Historical FS'!I15,0) -> 0.12937757 | J17: =IFERROR('Historical FS'!J15,0) -> 0.1380419 | ... L17: =IFERROR('Historical FS'!L15,0) -> 0.151592 | N17: =IFERROR(AVERAGE(C17:L17),0) -> 0.14043895 | O17: =IFERROR(MEDIAN(C17:L17),0) -> 0.1405519
B18: Depreciation%Sales | C18: =IFERROR('Historical FS'!C21,0) -> 0.022227475 | D18: =IFERROR('Historical FS'!D21,0) -> 0.021425239 | E18: =IFERROR('Historical FS'!E21,0) -> 0.03233554 | F18: =IFERROR('Historical FS'!F21,0) -> 0.038617107 | G18: =IFERROR('Historical FS'!G21,0) -> 0.036442576 | H18: =IFERROR('Historical FS'!H21,0) -> 0.028052374 | I18: =IFERROR('Historical FS'!I21,0) -> 0.024878373 | J18: =IFERROR('Historical FS'!J21,0) -> 0.024031737 | ... L18: =IFERROR('Historical FS'!L21,0) -> 0.034534226 | N18: =IFERROR(AVERAGE(C18:L18),0) -> 0.029281514 | O18: =IFERROR(MEDIAN(C18:L18),0) -> 0.029161436
B19: OperatingIncome%Sales | C19: =C13 -> 0.17653511 | D19: =D13 -> 0.16901136 | E19: =E13 -> 0.16334609 | F19: =F13 -> 0.16729643 | G19: =G13 -> 0.18718599 | H19: =H13 -> 0.13701287 | I19: =I13 -> 0.15662629 | J19: =J13 -> 0.18966139 | ... L19: =L13 -> 0.15374749 | N19: =IFERROR(AVERAGE(C19:L19),0) -> 0.16472975 | O19: =IFERROR(MEDIAN(C19:L19),0) -> 0.16532126
B21: Return on Capital Employed | C21: =IFERROR('Historical FS'!C23/(SUM('Historical FS'!C53:C55)),0) -> 0.32568534 | D21: =IFERROR('Historical FS'!D23/(SUM('Historical FS'!D53:D55)),0) -> 0.31793919 | E21: =IFERROR('Historical FS'!E23/(SUM('Historical FS'!E53:E55)),0) -> 0.29126565 | F21: =IFERROR('Historical FS'!F23/(SUM('Historical FS'!F53:F55)),0) -> 0.30059314 | G21: =IFERROR('Historical FS'!G23/(SUM('Historical FS'!G53:G55)),0) -> 0.29241025 | H21: =IFERROR('Historical FS'!H23/(SUM('Historical FS'!H53:H55)),0) -> 0.25893857 | I21: =IFERROR('Historical FS'!I23/(SUM('Historical FS'!I53:I55)),0) -> 0.30135929 | J21: =IFERROR('Historical FS'!J23/(SUM('Historical FS'!J53:J55)),0) -> 0.31750609 | ... L21: =IFERROR('Historical FS'!L23/(SUM('Historical FS'!L53:L55)),0) -> 0.21623587 | N21: =IFERROR(AVERAGE(C21:L21),0) -> 0.28515252 | O21: =IFERROR(MEDIAN(C21:L21),0) -> 0.2965017
B22: Retained Earnings% | C22: =IFERROR('Historical FS'!C50,0) -> 0.49058228 | D22: =IFERROR('Historical FS'!D50,0) -> 0.5907167 | E22: =IFERROR('Historical FS'!E50,0) -> 0.53283981 | F22: =IFERROR('Historical FS'!F50,0) -> 0.57450364 | G22: =IFERROR('Historical FS'!G50,0) -> 0.45459961 | H22: =IFERROR('Historical FS'!H50,0) -> 0.3938863 | I22: =IFERROR('Historical FS'!I50,0) -> 0.40085719 | J22: =IFERROR('Historical FS'!J50,0) -> 0.41501732 | ... L22: =IFERROR('Historical FS'!L50,0) -> 0.3901534 | N22: =IFERROR(AVERAGE(C22:L22),0) -> 0.45944868 | O22: =IFERROR(MEDIAN(C22:L22),0) -> 0.43480846
B23: Return on Equity% | C23: =IFERROR('Historical FS'!C39/('Historical FS'!C53+'Historical FS'!C54),0) -> 0.25505761 | D23: =IFERROR('Historical FS'!D39/('Historical FS'!D53+'Historical FS'!D54),0) -> 0.24243451 | E23: =IFERROR('Historical FS'!E39/('Historical FS'!E53+'Historical FS'!E54),0) -> 0.22764465 | F23: =IFERROR('Historical FS'!F39/('Historical FS'!F53+'Historical FS'!F54),0) -> 0.26704119 | G23: =IFERROR('Historical FS'!G39/('Historical FS'!G53+'Historical FS'!G54),0) -> 0.24513657 | H23: =IFERROR('Historical FS'!H39/('Historical FS'!H53+'Historical FS'!H54),0) -> 0.21942272 | I23: =IFERROR('Historical FS'!I39/('Historical FS'!I53+'Historical FS'!I54),0) -> 0.25677782 | J23: =IFERROR('Historical FS'!J39/('Historical FS'!J53+'Historical FS'!J54),0) -> 0.29154969 | ... L23: =IFERROR('Historical FS'!L39/('Historical FS'!L53+'Historical FS'!L54),0) -> 0.20238784 | N23: =IFERROR(AVERAGE(C23:L23),0) -> 0.23964869 | O23: =IFERROR(MEDIAN(C23:L23),0) -> 0.24378554
B24: Sustainable Growth Rate | C24: =IFERROR(C22*C23,0) -> 0.12512674 | D24: =IFERROR(D22*D23,0) -> 0.14321011 | E24: =IFERROR(E22*E23,0) -> 0.12129813 | F24: =IFERROR(F22*F23,0) -> 0.15341614 | G24: =IFERROR(G22*G23,0) -> 0.11143899 | H24: =IFERROR(H22*H23,0) -> 0.086427601 | I24: =IFERROR(I22*I23,0) -> 0.10293124 | J24: =IFERROR(J22*J23,0) -> 0.12099817 | ... L24: =IFERROR(L22*L23,0) -> 0.078962305 | N24: =IFERROR(AVERAGE(C24:L24),0) -> 0.1110223 | O24: =IFERROR(MEDIAN(C24:L24),0) -> 0.11621858
B25: Interest Coverage Ratio | C25: =IFERROR('Historical FS'!C23/'Historical FS'!C29,0) -> 71.22877 | D25: =IFERROR('Historical FS'!D23/'Historical FS'!D29,0) -> 68.568604 | E25: =IFERROR('Historical FS'!E23/'Historical FS'!E29,0) -> 28.449353 | F25: =IFERROR('Historical FS'!F23/'Historical FS'!F29,0) -> 33.042803 | G25: =IFERROR('Historical FS'!G23/'Historical FS'!G29,0) -> 44.355888 | H25: =IFERROR('Historical FS'!H23/'Historical FS'!H29,0) -> 41.790693 | I25: =IFERROR('Historical FS'!I23/'Historical FS'!I29,0) -> 37.395777 | J25: =IFERROR('Historical FS'!J23/'Historical FS'!J29,0) -> 32.811717 | ... L25: =IFERROR('Historical FS'!L23/'Historical FS'!L29,0) -> 27.99693 | N25: =IFERROR(AVERAGE(C25:L25),0) -> 40.757635 | O25: =IFERROR(MEDIAN(C25:L25),0) -> 35.21929
B27: Debtor Turnover Ratio | C27: =IFERROR('Historical FS'!C5/'Historical FS'!C65,0) -> 10.411994 | D27: =IFERROR('Historical FS'!D5/'Historical FS'!D65,0) -> 9.7216332 | E27: =IFERROR('Historical FS'!E5/'Historical FS'!E65,0) -> 10.087468 | F27: =IFERROR('Historical FS'!F5/'Historical FS'!F65,0) -> 11.258369 | G27: =IFERROR('Historical FS'!G5/'Historical FS'!G65,0) -> 8.344109 | H27: =IFERROR('Historical FS'!H5/'Historical FS'!H65,0) -> 7.5169136 | I27: =IFERROR('Historical FS'!I5/'Historical FS'!I65,0) -> 7.4377909 | J27: =IFERROR('Historical FS'!J5/'Historical FS'!J65,0) -> 7.2600464 | ... L27: =IFERROR('Historical FS'!L5/'Historical FS'!L65,0) -> 7.9751535 | N27: =IFERROR(AVERAGE(C27:L27),0) -> 8.7873554 | O27: =IFERROR(MEDIAN(C27:L27),0) -> 8.1596312
B28: Creditor Turnover Ratio | C28: =IFERROR('Data Sheet'!B18/'Historical FS'!C113,0) -> 3.875507 | D28: =IFERROR('Data Sheet'!C18/'Historical FS'!D113,0) -> 3.7630417 | E28: =IFERROR('Data Sheet'!D18/'Historical FS'!E113,0) -> 4.166416 | F28: =IFERROR('Data Sheet'!E18/'Historical FS'!F113,0) -> 4.6710295 | G28: =IFERROR('Data Sheet'!F18/'Historical FS'!G113,0) -> 3.0853951 | H28: =IFERROR('Data Sheet'!G18/'Historical FS'!H113,0) -> 4.1122118 | I28: =IFERROR('Data Sheet'!H18/'Historical FS'!I113,0) -> 5.2229794 | J28: =IFERROR('Data Sheet'!I18/'Historical FS'!J113,0) -> 4.5447246 | ... L28: =IFERROR('Data Sheet'!K18/'Historical FS'!L113,0) -> 4.4374864 | N28: =IFERROR(AVERAGE(C28:L28),0) -> 4.2427781 | O28: =IFERROR(MEDIAN(C28:L28),0) -> 4.3019512
B29: Inventory Turnover | C29: =IFERROR('Historical FS'!C8/'Historical FS'!C66,0) -> 3.7049419 | D29: =IFERROR('Historical FS'!D8/'Historical FS'!D66,0) -> 4.21101 | E29: =IFERROR('Historical FS'!E8/'Historical FS'!E66,0) -> 4.0972646 | F29: =IFERROR('Historical FS'!F8/'Historical FS'!F66,0) -> 3.8816394 | G29: =IFERROR('Historical FS'!G8/'Historical FS'!G66,0) -> 3.6948007 | H29: =IFERROR('Historical FS'!H8/'Historical FS'!H66,0) -> 3.3464386 | I29: =IFERROR('Historical FS'!I8/'Historical FS'!I66,0) -> 3.8267715 | J29: =IFERROR('Historical FS'!J8/'Historical FS'!J66,0) -> 3.8845851 | ... L29: =IFERROR('Historical FS'!L8/'Historical FS'!L66,0) -> 4.089641 | N29: =IFERROR(AVERAGE(C29:L29),0) -> 3.8121578 | O29: =IFERROR(MEDIAN(C29:L29),0) -> 3.8542054
B30: Fixed Asset Turnover | C30: =IFERROR('Historical FS'!C5/'Historical FS'!C59,0) -> 4.5590724 | D30: =IFERROR('Historical FS'!D5/'Historical FS'!D59,0) -> 4.5078961 | E30: =IFERROR('Historical FS'!E5/'Historical FS'!E59,0) -> 2.9615874 | F30: =IFERROR('Historical FS'!F5/'Historical FS'!F59,0) -> 3.2222977 | G30: =IFERROR('Historical FS'!G5/'Historical FS'!G59,0) -> 3.7061903 | H30: =IFERROR('Historical FS'!H5/'Historical FS'!H59,0) -> 5.2728689 | I30: =IFERROR('Historical FS'!I5/'Historical FS'!I59,0) -> 5.9767488 | J30: =IFERROR('Historical FS'!J5/'Historical FS'!J59,0) -> 4.9666458 | ... L30: =IFERROR('Historical FS'!L5/'Historical FS'!L59,0) -> 3.6911314 | N30: =IFERROR(AVERAGE(C30:L30),0) -> 4.2541798 | O30: =IFERROR(MEDIAN(C30:L30),0) -> 4.1070432
B31: Capital Turnover Ratio | C31: =IFERROR('Historical FS'!C5/SUM('Historical FS'!C53:C55),0) -> 1.8448758 | D31: =IFERROR('Historical FS'!D5/SUM('Historical FS'!D53:D55),0) -> 1.8811706 | E31: =IFERROR('Historical FS'!E5/SUM('Historical FS'!E53:E55),0) -> 1.7831198 | F31: =IFERROR('Historical FS'!F5/SUM('Historical FS'!F53:F55),0) -> 1.7967696 | G31: =IFERROR('Historical FS'!G5/SUM('Historical FS'!G53:G55),0) -> 1.5621375 | H31: =IFERROR('Historical FS'!H5/SUM('Historical FS'!H53:H55),0) -> 1.8898849 | I31: =IFERROR('Historical FS'!I5/SUM('Historical FS'!I53:I55),0) -> 1.9240658 | J31: =IFERROR('Historical FS'!J5/SUM('Historical FS'!J53:J55),0) -> 1.6740681 | ... L31: =IFERROR('Historical FS'!L5/SUM('Historical FS'!L53:L55),0) -> 1.4064351 | N31: =IFERROR(AVERAGE(C31:L31),0) -> 1.7325711 | O31: =IFERROR(MEDIAN(C31:L31),0) -> 1.7899447
B33: (In Days)
B34: Debtor Days | C34: =IFERROR(365/C27,0) -> 35.055726 | D34: =IFERROR(365/D27,0) -> 37.545132 | E34: =IFERROR(365/E27,0) -> 36.183511 | F34: =IFERROR(365/F27,0) -> 32.420325 | G34: =IFERROR(365/G27,0) -> 43.743436 | H34: =IFERROR(365/H27,0) -> 48.557163 | I34: =IFERROR(365/I27,0) -> 49.073711 | J34: =IFERROR(365/J27,0) -> 50.275161 | ... L34: =IFERROR(365/L27,0) -> 45.767144 | N34: =IFERROR(AVERAGE(C34:L34),0) -> 42.505852 | O34: =IFERROR(MEDIAN(C34:L34),0) -> 44.75529
B35: Payable Days | C35: =IFERROR(365/C28,0) -> 94.181225 | D35: =IFERROR(365/D28,0) -> 96.996003 | E35: =IFERROR(365/E28,0) -> 87.605269 | F35: =IFERROR(365/F28,0) -> 78.141232 | G35: =IFERROR(365/G28,0) -> 118.29927 | H35: =IFERROR(365/H28,0) -> 88.760019 | I35: =IFERROR(365/I28,0) -> 69.883485 | J35: =IFERROR(365/J28,0) -> 80.312897 | ... L35: =IFERROR(365/L28,0) -> 82.253773 | N35: =IFERROR(AVERAGE(C35:L35),0) -> 87.667079 | O35: =IFERROR(MEDIAN(C35:L35),0) -> 84.929521
B36: Inventory Days | C36: =IFERROR(365/C29,0) -> 98.517065 | D36: =IFERROR(365/D29,0) -> 86.677543 | E36: =IFERROR(365/E29,0) -> 89.083823 | F36: =IFERROR(365/F29,0) -> 94.032434 | G36: =IFERROR(365/G29,0) -> 98.787466 | H36: =IFERROR(365/H29,0) -> 109.07118 | I36: =IFERROR(365/I29,0) -> 95.380663 | J36: =IFERROR(365/J29,0) -> 93.961129 | ... L36: =IFERROR(365/L29,0) -> 89.249888 | N36: =IFERROR(AVERAGE(C36:L36),0) -> 96.260625 | O36: =IFERROR(MEDIAN(C36:L36),0) -> 94.706549
B37: Cash Conversion cycle | C37: =IFERROR(C34+C36-C35,0) -> 39.391566 | D37: =IFERROR(D34+D36-D35,0) -> 27.226672 | E37: =IFERROR(E34+E36-E35,0) -> 37.662065 | F37: =IFERROR(F34+F36-F35,0) -> 48.311527 | G37: =IFERROR(G34+G36-G35,0) -> 24.231628 | H37: =IFERROR(H34+H36-H35,0) -> 68.868321 | I37: =IFERROR(I34+I36-I35,0) -> 74.570889 | J37: =IFERROR(J34+J36-J35,0) -> 63.923393 | ... L37: =IFERROR(L34+L36-L35,0) -> 52.763259 | N37: =IFERROR(AVERAGE(C37:L37),0) -> 51.099397 | O37: =IFERROR(MEDIAN(C37:L37),0) -> 50.537393
B39: CFO/Sales | C39: =IFERROR('Historical FS'!C83/'Historical FS'!C5,0) -> 0.10144742 | D39: =IFERROR('Historical FS'!D83/'Historical FS'!D5,0) -> 0.12559028 | E39: =IFERROR('Historical FS'!E83/'Historical FS'!E5,0) -> 0.12832554 | F39: =IFERROR('Historical FS'!F83/'Historical FS'!F5,0) -> 0.15026285 | G39: =IFERROR('Historical FS'!G83/'Historical FS'!G5,0) -> 0.16962353 | H39: =IFERROR('Historical FS'!H83/'Historical FS'!H5,0) -> 0.033916034 | I39: =IFERROR('Historical FS'!I83/'Historical FS'!I5,0) -> 0.12160544 | J39: =IFERROR('Historical FS'!J83/'Historical FS'!J5,0) -> 0.17196919 | ... L39: =IFERROR('Historical FS'!L83/'Historical FS'!L5,0) -> 0.19919322 | N39: =IFERROR(AVERAGE(C39:L39),0) -> 0.13324428 | O39: =IFERROR(MEDIAN(C39:L39),0) -> 0.12941744
B40: CFO/Total Assets | C40: =IFERROR('Historical FS'!C83/'Historical FS'!C70,0) -> 0.12317425 | D40: =IFERROR('Historical FS'!D83/'Historical FS'!D70,0) -> 0.15352222 | E40: =IFERROR('Historical FS'!E83/'Historical FS'!E70,0) -> 0.15194931 | F40: =IFERROR('Historical FS'!F83/'Historical FS'!F70,0) -> 0.18818972 | G40: =IFERROR('Historical FS'!G83/'Historical FS'!G70,0) -> 0.18093532 | H40: =IFERROR('Historical FS'!H83/'Historical FS'!H70,0) -> 0.042990745 | I40: =IFERROR('Historical FS'!I83/'Historical FS'!I70,0) -> 0.16268848 | J40: =IFERROR('Historical FS'!J83/'Historical FS'!J70,0) -> 0.2041419 | ... L40: =IFERROR('Historical FS'!L83/'Historical FS'!L70,0) -> 0.20533768 | N40: =IFERROR(AVERAGE(C40:L40),0) -> 0.15587034 | O40: =IFERROR(MEDIAN(C40:L40),0) -> 0.15810535
B41: CFO/Total Debt | C41: =IFERROR('Historical FS'!C83/'Historical FS'!C55,0) -> 2.7269158 | D41: =IFERROR('Historical FS'!D83/'Historical FS'!D55,0) -> 3.961157 | E41: =IFERROR('Historical FS'!E83/'Historical FS'!E55,0) -> 1.8710215 | F41: =IFERROR('Historical FS'!F83/'Historical FS'!F55,0) -> 2.7152436 | G41: =IFERROR('Historical FS'!G83/'Historical FS'!G55,0) -> 3.369255 | H41: =IFERROR('Historical FS'!H83/'Historical FS'!H55,0) -> 0.6219752 | I41: =IFERROR('Historical FS'!I83/'Historical FS'!I55,0) -> 2.170111 | J41: =IFERROR('Historical FS'!J83/'Historical FS'!J55,0) -> 2.4668806 | ... L41: =IFERROR('Historical FS'!L83/'Historical FS'!L55,0) -> 1.8040535 | N41: =IFERROR(AVERAGE(C41:L41),0) -> 2.3638683 | O41: =IFERROR(MEDIAN(C41:L41),0) -> 2.3184958

Sheet Projections
B2: ='Data Sheet'!$B$1& " - " &'Data Sheet'!A17& " Forecast 3 Methods" -> ASIAN PAINTS LTD - Sales Forecast 3 Methods
B4: Year Weight | C4: 1 | D4: =C4+1 -> 2 | E4: =D4+1 -> 3 | F4: =E4+1 -> 4 | G4: =F4+1 -> 5 | H4: =G4+1 -> 6 | I4: =H4+1 -> 7 | J4: =I4+1 -> 8 | K4: =J4+1 -> 9 | ... R4: =Q4+1 -> 16
B5: ='Historical FS'!B3 -> Years | C5: ='Historical FS'!C3 -> 42825 | D5: ='Historical FS'!D3 -> 43190 | E5: ='Historical FS'!E3 -> 43555 | F5: ='Historical FS'!F3 -> 43921 | G5: ='Historical FS'!G3 -> 44286 | H5: ='Historical FS'!H3 -> 44651 | I5: ='Historical FS'!I3 -> 45016 | ... L5: ='Historical FS'!L3 -> 46112 | M5: =EOMONTH(L5,12) -> 46477 | N5: =EOMONTH(M5,12) -> 46843 | O5: =EOMONTH(N5,12) -> 47208 | P5: =EOMONTH(O5,12) -> 47573 | Q5: =EOMONTH(P5,12) -> 47938 | R5: =EOMONTH(Q5,12) -> 48304
B6: ='Historical FS'!B5 -> Sales | C6: ='Historical FS'!C5 -> 15061.99 | D6: ='Historical FS'!D5 -> 16824.55 | E6: ='Historical FS'!E5 -> 19240.13 | F6: ='Historical FS'!F5 -> 20211.25 | G6: ='Historical FS'!G5 -> 21712.79 | H6: ='Historical FS'!H5 -> 29101.28 | I6: ='Historical FS'!I5 -> 34488.59 | ... L6: ='Historical FS'!L5 -> 35583.54 | M6: {=_xlfn.XLOOKUP(F15,B19:B21,M19:R21,"Error",0)} -> 39318.457 | N6: 43445.399 | O6: 48005.513 | P6: 53044.264 | Q6: 58611.893 | R6: 64763.912
B7: ='Historical FS'!B6 -> Sales Growth | D7: =D6/C6-1 -> 0.11702039 | E7: =E6/D6-1 -> 0.14357472 | F7: =F6/E6-1 -> 0.050473671 | G7: =G6/F6-1 -> 0.074292288 | H7: =H6/G6-1 -> 0.34028285 | I7: =I6/H6-1 -> 0.18512278 | J7: =J6/I6-1 -> 0.029173127 | K7: =K6/J6-1 -> -0.044770308 | ... R7: =R6/Q6-1 -> 0.10496194
B9: Growth Rate Methods (single implied annual rate)
B11: Arithmetic Mean of YoY Growth (FY18-FY26) | F11: =AVERAGE($D$7:$L$7) -> 0.10496194
B12: Geometric Mean / CAGR (FY17-FY26) | F12: =_xlfn.RRI($L$4-1,$C$6,$L$6) -> 0.10023435
B13: Log-Linear Regression (implied CAGR) | F13: {=EXP(SLOPE(LN($C$6:$L$6),$C$4:$L$4))-1} -> 0.11256704
B15: Select Method for Forecast | F15: Arithmetic Mean method
B17: Sales Forecast by Method (₹ Cr)
B19: Arithmetic Mean method | M19: =L6*(1+$F$11) -> 39318.457 | N19: =M19*(1+$F$11) -> 43445.399 | O19: =N19*(1+$F$11) -> 48005.513 | P19: =O19*(1+$F$11) -> 53044.264 | Q19: =P19*(1+$F$11) -> 58611.893 | R19: =Q19*(1+$F$11) -> 64763.912
B20: Geometric Mean method | M20: =$L$6*(1+$F$12) -> 39150.233 | N20: =M20*(1+$F$12) -> 43074.431 | O20: =N20*(1+$F$12) -> 47391.969 | P20: =O20*(1+$F$12) -> 52142.272 | Q20: =P20*(1+$F$12) -> 57368.719 | R20: =Q20*(1+$F$12) -> 63119.035
B21: Log-Linear Regression method | M21: =$L$6*(1+$F$13) -> 39589.074 | N21: =M21*(1+$F$13) -> 44045.499 | O21: =N21*(1+$F$13) -> 49003.57 | P21: =O21*(1+$F$13) -> 54519.757 | Q21: =P21*(1+$F$13) -> 60656.885 | R21: =Q21*(1+$F$13) -> 67484.851
B24: ='Data Sheet'!$B$1& " - " &'Historical FS'!B17& " Forecast 3 Methods" -> ASIAN PAINTS LTD - EBITDA Forecast 3 Methods
B26: Year Weight | C26: 1 | D26: =C26+1 -> 2 | E26: =D26+1 -> 3 | F26: =E26+1 -> 4 | G26: =F26+1 -> 5 | H26: =G26+1 -> 6 | I26: =H26+1 -> 7 | J26: =I26+1 -> 8 | K26: =J26+1 -> 9 | ... R26: =Q26+1 -> 16
B27: ='Historical FS'!B3 -> Years | C27: ='Historical FS'!C3 -> 42825 | D27: ='Historical FS'!D3 -> 43190 | E27: ='Historical FS'!E3 -> 43555 | F27: ='Historical FS'!F3 -> 43921 | G27: ='Historical FS'!G3 -> 44286 | H27: ='Historical FS'!H3 -> 44651 | I27: ='Historical FS'!I3 -> 45016 | ... L27: ='Historical FS'!L3 -> 46112 | M27: =L27+365 -> 46477 | N27: =M27+365 -> 46842 | O27: =N27+365 -> 47207 | P27: =O27+365 -> 47572 | Q27: =P27+365 -> 47937 | R27: =Q27+365 -> 48302
B28: EBITDA | C28: ='Historical FS'!C17 -> 2993.76 | D28: ='Historical FS'!D17 -> 3204.01 | E28: ='Historical FS'!E17 -> 3764.94 | F28: ='Historical FS'!F17 -> 4161.77 | G28: ='Historical FS'!G17 -> 4855.6 | H28: ='Historical FS'!H17 -> 4803.61 | I28: ='Historical FS'!I17 -> 6259.84 | J28: ='Historical FS'!J17 -> 7584.98 | ... L28: ='Historical FS'!L17 -> 6699.73 | M28: {=_xlfn.XLOOKUP(F38,B42:B44,M42:R44,"Error",0)} -> 7391.1981 | N28: 8154.0316 | O28: 8995.5958 | P28: 9924.0165 | Q28: 10948.258 | R28: 12078.21
B29: ='Historical FS'!B18 -> EBITDA Margins | C29: =C28/C6 -> 0.19876258 | D29: =D28/D6 -> 0.19043659 | E29: =E28/E6 -> 0.19568163 | F29: =F28/F6 -> 0.20591354 | G29: =G28/G6 -> 0.22362856 | H29: =H28/H6 -> 0.16506525 | I29: =I28/I6 -> 0.18150467 | J29: =J28/J6 -> 0.21369313 | ... R29: =R28/R6 -> 0.18649599
B30: EBITDA Growth | D30: =D28/C28-1 -> 0.070229411 | E30: =E28/D28-1 -> 0.17507124 | F30: =F28/E28-1 -> 0.10540141 | G30: =G28/F28-1 -> 0.16671512 | H30: =H28/G28-1 -> -0.010707225 | I30: =I28/H28-1 -> 0.30315325 | J30: =J28/I28-1 -> 0.21168912 | K30: =K28/J28-1 -> -0.20814425 | ... R30: =R28/Q28-1 -> 0.10320836
B32: Growth Rate Methods (single implied annual rate)
B34: Arithmetic Mean of YoY EBITDA Growth (FY18-FY26) | F34: =AVERAGE($D$30:$L$30) -> 0.10320836
B35: Geometric Mean / CAGR (FY17-FY26) | F35: =_xlfn.RRI($L$26-1,$C$28,$L$28) -> 0.093631842
B36: Log-Linear Regression (implied CAGR) | F36: {=EXP(SLOPE(LN($C$28:$L$28),$C$26:$L$26))-1} -> 0.10426463
B38: Select Method for Forecast | F38: Arithmetic Mean method
B40: EBITDA Forecast by Method (₹ Cr)
B42: Arithmetic Mean method | M42: =$L$28*(1+$F$34) -> 7391.1981 | N42: =M42*(1+$F$34) -> 8154.0316 | O42: =N42*(1+$F$34) -> 8995.5958 | P42: =O42*(1+$F$34) -> 9924.0165 | Q42: =P42*(1+$F$34) -> 10948.258 | R42: =Q42*(1+$F$34) -> 12078.21
B43: Geometric Mean method | M43: =$L$28*(1+$F$35) -> 7327.0381 | N43: =M43*(1+$F$35) -> 8013.0821 | O43: =N43*(1+$F$35) -> 8763.3618 | P43: =O43*(1+$F$35) -> 9583.8915 | Q43: =P43*(1+$F$35) -> 10481.249 | R43: =Q43*(1+$F$35) -> 11462.628
B44: Log-Linear Regression method | M44: =$L$28*(1+$F$36) -> 7398.2749 | N44: =M44*(1+$F$36) -> 8169.6532 | O44: =N44*(1+$F$36) -> 9021.4591 | P44: =O44*(1+$F$36) -> 9962.0782 | Q44: =P44*(1+$F$36) -> 11000.771 | R44: =Q44*(1+$F$36) -> 12147.762

Sheet Sensitivity Analysis
B2: Base Case | G2: FY27
B3: Sales Growth Rate | G3: =Projections!$M$19/Projections!$L$6-1 -> 0.10496194
B4: EBITDA Margin | G4: =Projections!$M$42/Projections!$M$19 -> 0.18798291
B6: Base Sales at Base Growth Rate for FY27 | G6: =Projections!$L$6*(1+$G$3) -> 39318.457
B7: FY27 EBITDA - Base Case Output | G7: =G6*G4 -> 7391.1981
B9: Senstivity Analysis
B10: Senstivity to Sales Growth and EBITDA margin
B12: =G7 -> 7391.1981 | C12: =D12-0.04 -> 0.024961942 | D12: =E12-0.04 -> 0.064961942 | E12: =Projections!$M$19/Projections!$L$6-1 -> 0.10496194 | F12: =E12+0.04 -> 0.14496194 | G12: =F12+0.04 -> 0.18496194
B13: =B14-0.02 -> 0.14798291 | C13: 5397.1994 | D13: 5607.8296 | E13: 5818.4598 | F13: 6029.0901 | G13: 6239.7203
B14: =B15-0.02 -> 0.16798291 | C14: 6126.6349 | D14: 6365.7319 | E14: 6604.829 | F14: 6843.9261 | G14: 7083.0231
B15: =Projections!$M$42/Projections!$M$19 -> 0.18798291 | C15: 6856.0703 | D15: 7123.6342 | E15: 7391.1981 | F15: 7658.762 | G15: 7926.3259
B16: =B15+0.02 -> 0.20798291 | C16: 7585.5058 | D16: 7881.5366 | E16: 8177.5673 | F16: 8473.598 | G16: 8769.6288
B17: =B16+0.02 -> 0.22798291 | C17: 8314.9413 | D17: 8639.4389 | E17: 8963.9364 | F17: 9288.434 | G17: 9612.9316
B19: Range: | C19: ="₹"&TEXT(MIN(C13:G17),"#,##0")&"- ₹"&TEXT(MAX(C13:G17),"#,##0") -> ₹5,397- ₹9,613
B20: Vs Base : | C20: =TEXT((C13-E15)/E15,"+0%;-0%")& " / " &TEXT((G17-E15)/E15,"+0%;-0%") -> -27% / +30%
